Workbook

Sheet How to Fill
B1: InGage Source Library - Intern Collection Guide
B2: Goal: find every official source document, record exact details, save the official file, and prove it is the official version. This sheet becomes the database Source Library.
A4: books.toscrape.com | B4: Your daily routine
B5: Step 1 | C5: Open the Source Register tab and filter "Assigned To" to your name. Work top to bottom.
B6: Step 2 | C6: For each row: start from "Start Here (hint)" or the Watch Feeds tab, find the document on the OFFICIAL site.
B7: Step 3 | C7: Download the file in your browser. Save it in the shared folder under the category folder (e.g. 04_Accreditation). Name: Authority_Short_Title_Year.pdf, e.g. UGC_PhD_Regulations_2022.pdf
B8: Step 4 | C8: Fill every blue column. Get the SHA-256 in PowerShell: Get-FileHash "D:\path\file.pdf" -Algorithm SHA256
B9: Step 5 | C9: Keep going until "Row Check" says OK. Then the supervisor verifies it (orange columns).
B10: Step 6 | C10: Found more documents (amendments, other institution types, programmes)? Add a NEW row at the bottom for each one. Use the next free Row ID.
B11: Step 7 | C11: End of day: add one line to the Daily Log tab (rows done, hours, blockers).
B13: Rules - read carefully
B14: Official sites only | C14: Download only from the authority's own website (ugc.gov.in, naac.gov.in, nbaind.org, aicte-india.org, dgt.gov.in, nirfindia.org, meity.gov.in, cert-in.org.in, indiacode.nic.in, nist.gov, unesco.org...). Never from Scribd, coaching sites, blogs or Google Drive copies.
B15: Collect by hand | C15: Use a normal browser. Do not run scraping scripts or bulk downloaders - these sites block them (that is why 6 downloads failed in v0.1). Never try to get around a login, CAPTCHA or block.
B16: Login or blocked? | C16: Set Collection Status to "Blocked - portal/login", fill the listing URL, explain in Notes, and tell the supervisor in the Daily Log. Do not create accounts.
B17: Licensed standards | C17: ISO/IEC and other paid standards: record the official page, edition and title only. Set "Licensed - link only". Never download or copy their text.
B18: One row = one version | C18: A new edition or an amendment is a NEW row with the same Source Code and a different Version. Fill "Supersedes / Amends". Never overwrite or delete an older row.
B19: Exact, not guessed | C19: Titles, versions and dates must be copied from the document itself. If unsure, leave Current Status "Not verified" and explain in Notes.
B20: Source Role | C20: Pre-filled as a suggestion. Do not change it without asking - the manager decides which sources are Mandatory vs guidance, so a market report is never mistaken for a legal requirement.
B22: Colour legend
B23: Blue header | C23: Intern fills these columns.
B24: Grey header | C24: Automatic or hint - do not edit (Row ID, Start Here, Row Check).
B25: Orange header | C25: Supervisor only (QA Status, QA By, QA Comment).
B26: Green row | C26: Worked example (DATA-001, DPDP Act). Copy its style.
B27: Row Check | C27: Green OK = complete. Yellow = something missing (it tells you what). Grey = not started.
B28: Red Source Code | C28: Same code and version entered twice - remove the duplicate.
B30: Tabs
B31: Source Register | C31: Main work sheet. Hover a column header to see what to enter.
B32: Progress | C32: Automatic counts per intern and per category.
B33: Watch Feeds | C33: Official register pages to search from. Record "Last Checked" when you visit one.
B34: Benchmark Catalogue | C34: The 60 benchmarks - optional, for "Related Benchmark IDs".
B35: Daily Log | C35: One line per intern per day.
B36: Lists | C36: Dropdown values. Rename "Intern A / Intern B" here and in the register before starting.
B38: Pre-filled rows
B39: 89 starter rows come from the manager's Source Pack v0.2, the v0.1 manifest and the "complete library" brief. 13 are already downloaded (size, pages and SHA-256 computed from the manager's files) - only dates, version and status still need checking from the document.

Sheet Source Register
A1: InGage Source Library - Source Register (one row = one document version)
A2: Blue headers = intern fills. Grey = automatic / hint. Orange = supervisor only. Green row = worked example (S-001 style). Read the "How to Fill" tab first.
A4: Row ID | B4: Assigned To | C4: Category | D4: Authority | E4: Authority Kind | F4: Source Role (suggested) | G4: Source Code | H4: Official Title (exact) | I4: Document Type | J4: Version / Edition | K4: Issued On | L4: Effective From | M4: Current Status | N4: Supersedes / Amends | O4: Applies To | P4: Programme / Trade Scope | Q4: Listing Page URL | R4: Direct Document URL | S4: Official Domain? | T4: Collection Status | U4: Local File (folder/name) | V4: File Size (KB) | W4: Pages | X4: SHA-256 Checksum | Y4: Licensed Content? | Z4: Review Cadence (months) | AA4: Watcher Feed Type | AB4: Related Benchmark IDs | AC4: Collected On | AD4: Notes | AE4: Start Here (hint) | AF4: Row Check | AG4: QA Status | AH4: QA By / Date | AI4: QA Comment
A5: S-001 | B5: Intern A | C5: 1. Accreditation & Quality | D5: NAAC | E5: accreditation | F5: Authoritative quality framework | G5: NAAC-001 | H5: NAAC Criteria and Key Indicators Annexure (with weightages) | I5: Manual | M5: Not verified | O5: All HEIs | Q5: https://naac.gov.in/index.php/en/component/search/?searchword=Criteria%20and%20Key%20Indicators%20Annexure&searchphrase=all | T5: Downloaded | U5: https://drive.google.com/drive/folders/1Hbqu-ekfL3sVsfM-57H3KDnewAmpZAQq?usp=drive_link | Y5: No | Z5: 3 | AA5: web_page | AE5: https://assessmentonline.naac.gov.in/ | AF5: =IF($H5="","",IF($T5="To find","Not started",IF(($C5="")+($D5="")+($E5="")+($G5="")+($I5="")+($M5="")+($O5="")+($S5="")>0,"Missing basic details",IF(AND($T5="Downloaded",($R5="")+($U5="")+($V5="")+(($W5="")*(RIGHT(LOWER($U5),4)=".pdf"))>0),"Add file details",IF(AND($T5="Downloaded",LEN($X5)<>64),"Check SHA-256",IF(AND($Q5="",$R5=""),"Add a URL",IF($S5="No","Not official - replace",IF($M5="Not verified","Verify status","OK")))))))) | AG5: Needs fix | AH5: Auto-QA 12-Oct-2026 | AI5: 1) Drive link is a FOLDER - link the exact file (drive.google.com/file/d/...). | 2) Downloaded but missing: Direct Document URL, File Size (KB), SHA-256 Checksum, Version / Edition, Issued On. | 3) Set Current Status from the document (Current / Superseded ...).
A6: S-002 | B6: Intern A | C6: 1. Accreditation & Quality | D6: NAAC | E6: accreditation | F6: Authoritative quality framework | G6: NAAC-002-UNIV | H6: NAAC SSR Manual and QIF - Universities | I6: SSR / QIF / SAR | M6: Not verified | O6: Universities | Q6: https://iqac.annauniv.edu/AAA%26R/NAAC_Revised_University_Manual_Dec_2022.pdf | T6: Downloaded | U6: https://drive.google.com/drive/folders/1Hbqu-ekfL3sVsfM-57H3KDnewAmpZAQq?usp=drive_link | Y6: No | Z6: 1 | AA6: document_index | AE6: https://assessmentonline.naac.gov.in/ | AF6: =IF($H6="","",IF($T6="To find","Not started",IF(($C6="")+($D6="")+($E6="")+($G6="")+($I6="")+($M6="")+($O6="")+($S6="")>0,"Missing basic details",IF(AND($T6="Downloaded",($R6="")+($U6="")+($V6="")+(($W6="")*(RIGHT(LOWER($U6),4)=".pdf"))>0),"Add file details",IF(AND($T6="Downloaded",LEN($X6)<>64),"Check SHA-256",IF(AND($Q6="",$R6=""),"Add a URL",IF($S6="No","Not official - replace",IF($M6="Not verified","Verify status","OK")))))))) | AG6: Needs fix | AH6: Auto-QA 12-Oct-2026 | AI6: 1) Listing Page URL is on iqac.annauniv.edu, not the official site - replace with the authority's own link (copies on college or third-party sites are not accepted). | 2) Drive link is a FOLDER - link the exact file (drive.google.com/file/d/...). | 3) Downloaded but missing: Direct Document URL, File Size (KB), SHA-256 Checksum, Version / Edition, Issued On. | 4) Set Current Status from the document (Current / Superseded ...).
A7: S-003 | B7: Intern A | C7: 1. Accreditation & Quality | D7: NAAC | E7: accreditation | F7: Authoritative quality framework | G7: NAAC-002-AUTO | H7: NAAC SSR Manual and QIF - Autonomous Colleges | I7: SSR / QIF / SAR | M7: Not verified | O7: Autonomous colleges | Q7: https://mits.ac.in/assets/pdf/iqac/NAAC%20Autonomous_College%20Manual_29-03-2023_Updated_9-8-2023.pdf | T7: Downloaded | U7: https://drive.google.com/drive/folders/1Hbqu-ekfL3sVsfM-57H3KDnewAmpZAQq?usp=drive_link | Y7: No | Z7: 1 | AA7: document_index | AE7: https://assessmentonline.naac.gov.in/ | AF7: =IF($H7="","",IF($T7="To find","Not started",IF(($C7="")+($D7="")+($E7="")+($G7="")+($I7="")+($M7="")+($O7="")+($S7="")>0,"Missing basic details",IF(AND($T7="Downloaded",($R7="")+($U7="")+($V7="")+(($W7="")*(RIGHT(LOWER($U7),4)=".pdf"))>0),"Add file details",IF(AND($T7="Downloaded",LEN($X7)<>64),"Check SHA-256",IF(AND($Q7="",$R7=""),"Add a URL",IF($S7="No","Not official - replace",IF($M7="Not verified","Verify status","OK")))))))) | AG7: Needs fix | AH7: Auto-QA 12-Oct-2026 | AI7: 1) Listing Page URL is on mits.ac.in, not the official site - replace with the authority's own link (copies on college or third-party sites are not accepted). | 2) Drive link is a FOLDER - link the exact file (drive.google.com/file/d/...). | 3) Downloaded but missing: Direct Document URL, File Size (KB), SHA-256 Checksum, Version / Edition, Issued On. | 4) Set Current Status from the document (Current / Superseded ...).
A8: S-004 | B8: Intern A | C8: 1. Accreditation & Quality | D8: NAAC | E8: accreditation | F8: Authoritative quality framework | G8: NAAC-002-AFF | H8: NAAC SSR Manual and QIF - Affiliated / Constituent Colleges | I8: SSR / QIF / SAR | M8: Not verified | O8: Affiliated and constituent colleges | Q8: https://www.ramajeemahavidyalaya.edu.in/uplfile/revised_ssr.pdf | T8: Downloaded | U8: https://drive.google.com/drive/folders/1Hbqu-ekfL3sVsfM-57H3KDnewAmpZAQq?usp=drive_link | Y8: No | Z8: 1 | AA8: document_index | AE8: https://assessmentonline.naac.gov.in/ | AF8: =IF($H8="","",IF($T8="To find","Not started",IF(($C8="")+($D8="")+($E8="")+($G8="")+($I8="")+($M8="")+($O8="")+($S8="")>0,"Missing basic details",IF(AND($T8="Downloaded",($R8="")+($U8="")+($V8="")+(($W8="")*(RIGHT(LOWER($U8),4)=".pdf"))>0),"Add file details",IF(AND($T8="Downloaded",LEN($X8)<>64),"Check SHA-256",IF(AND($Q8="",$R8=""),"Add a URL",IF($S8="No","Not official - replace",IF($M8="Not verified","Verify status","OK")))))))) | AG8: Needs fix | AH8: Auto-QA 12-Oct-2026 | AI8: 1) Listing Page URL is on ramajeemahavidyalaya.edu.in, not the official site - replace with the authority's own link (copies on college or third-party sites are not accepted). | 2) Drive link is a FOLDER - link the exact file (drive.google.com/file/d/...). | 3) Downloaded but missing: Direct Document URL, File Size (KB), SHA-256 Checksum, Version / Edition, Issued On. | 4) Set Current Status from the document (Current / Superseded ...).
A9: S-005 | B9: Intern A | C9: 1. Accreditation & Quality | D9: NAAC | E9: accreditation | F9: Authoritative quality framework | G9: NAAC-003 | H9: NAAC data templates and metric-wise evidence instructions | I9: Data template | M9: Not verified | Q9: https://tiastc.tecnia.in/naac-manuals/ | T9: Downloaded | U9: https://drive.google.com/drive/folders/1Hbqu-ekfL3sVsfM-57H3KDnewAmpZAQq?usp=drive_link | Y9: No | Z9: 1 | AA9: document_index | AE9: https://assessmentonline.naac.gov.in/ | AF9: =IF($H9="","",IF($T9="To find","Not started",IF(($C9="")+($D9="")+($E9="")+($G9="")+($I9="")+($M9="")+($O9="")+($S9="")>0,"Missing basic details",IF(AND($T9="Downloaded",($R9="")+($U9="")+($V9="")+(($W9="")*(RIGHT(LOWER($U9),4)=".pdf"))>0),"Add file details",IF(AND($T9="Downloaded",LEN($X9)<>64),"Check SHA-256",IF(AND($Q9="",$R9=""),"Add a URL",IF($S9="No","Not official - replace",IF($M9="Not verified","Verify status","OK")))))))) | AG9: Needs fix | AH9: Auto-QA 12-Oct-2026 | AI9: 1) Listing Page URL is on tiastc.tecnia.in, not the official site - replace with the authority's own link (copies on college or third-party sites are not accepted). | 2) Drive link is a FOLDER - link the exact file (drive.google.com/file/d/...). | 3) Downloaded but missing: Direct Document URL, File Size (KB), SHA-256 Checksum, Version / Edition, Issued On. | 4) Set Current Status from the document (Current / Superseded ...). | 5) Fill "Applies To".
A10: S-006 | B10: Intern A | C10: 1. Accreditation & Quality | D10: NAAC | E10: accreditation | F10: Authoritative quality framework | G10: NAAC-004 | H10: NAAC SOPs and assessment manuals (data validation, peer team visit) | I10: SOP | M10: Not verified | Q10: https://iqac.annauniv.edu/AAA%26R/NAAC_Revised_University_SOP_Dec_2022.pdf | T10: Downloaded | U10: https://drive.google.com/drive/folders/1Hbqu-ekfL3sVsfM-57H3KDnewAmpZAQq?usp=drive_link | Y10: No | Z10: 3 | AA10: document_index | AE10: https://assessmentonline.naac.gov.in/ | AF10: =IF($H10="","",IF($T10="To find","Not started",IF(($C10="")+($D10="")+($E10="")+($G10="")+($I10="")+($M10="")+($O10="")+($S10="")>0,"Missing basic details",IF(AND($T10="Downloaded",($R10="")+($U10="")+($V10="")+(($W10="")*(RIGHT(LOWER($U10),4)=".pdf"))>0),"Add file details",IF(AND($T10="Downloaded",LEN($X10)<>64),"Check SHA-256",IF(AND($Q10="",$R10=""),"Add a URL",IF($S10="No","Not official - replace",IF($M10="Not verified","Verify status","OK")))))))) | AG10: Needs fix | AH10: Auto-QA 12-Oct-2026 | AI10: 1) Listing Page URL is on iqac.annauniv.edu, not the official site - replace with the authority's own link (copies on college or third-party sites are not accepted). | 2) Drive link is a FOLDER - link the exact file (drive.google.com/file/d/...). | 3) Downloaded but missing: Direct Document URL, File Size (KB), SHA-256 Checksum, Version / Edition, Issued On. | 4) Set Current Status from the document (Current / Superseded ...). | 5) Fill "Applies To".
A11: S-007 | B11: Intern A | C11: 1. Accreditation & Quality | D11: NBA | E11: accreditation | F11: Authoritative quality framework | G11: NBA-001 | H11: NBA Accreditation Documents portal (register snapshot) | I11: Register page | M11: Not verified | O11: NBA-applicable programmes | Q11: https://www.nbaind.org/Downloads/Documents | R11: https://www.nbaind.org/Downloads/Documents | S11: Yes | T11: Downloaded | U11: https://drive.google.com/drive/folders/1a1fiRcDfuN8O2-xMdYuGnhc-ITAlNAJj?usp=drive_link | V11: 228 | X11: 16e44ce55fb25881aec7bc5dd5183b052a91baab9bfe89a691277f0720334f7a | Y11: No | Z11: 3 | AA11: document_index | AD11: Snapshot from manager v0.1 pack. Use this page to find NBA-004 to NBA-009. | AF11: =IF($H11="","",IF($T11="To find","Not started",IF(($C11="")+($D11="")+($E11="")+($G11="")+($I11="")+($M11="")+($O11="")+($S11="")>0,"Missing basic details",IF(AND($T11="Downloaded",($R11="")+($U11="")+($V11="")+(($W11="")*(RIGHT(LOWER($U11),4)=".pdf"))>0),"Add file details",IF(AND($T11="Downloaded",LEN($X11)<>64),"Check SHA-256",IF(AND($Q11="",$R11=""),"Add a URL",IF($S11="No","Not official - replace",IF($M11="Not verified","Verify status","OK")))))))) | AG11: Needs fix | AH11: Auto-QA 12-Oct-2026 | AI11: 1) Drive link is a FOLDER - link the exact file (drive.google.com/file/d/...). | 2) Downloaded but missing: Version / Edition, Issued On. | 3) Set Current Status from the document (Current / Superseded ...).
A12: S-008 | B12: Intern A | C12: 1. Accreditation & Quality | D12: NBA | E12: accreditation | F12: Authoritative quality framework | G12: NBA-002 | H12: NBA General Manual for Accreditation | I12: Manual | M12: Not verified | O12: NBA-applicable programmes | Q12: https://www.nbaind.org/Downloads/Documents | R12: https://www.nbaind.org/files/General_Manual_V1.0_Format_20240423170211.pdf | S12: Yes | T12: Downloaded | U12: https://drive.google.com/file/d/1nAVg_Y7d-ohG76D-MZme6rA1rgDleGzg/view?usp=drive_link | V12: 316 | W12: 52 | X12: 84204319da2c073e0c166cda880bbcb620d0fe0d2bd79a8b8c42319dce9016d6 | Y12: No | Z12: 3 | AA12: document_index | AD12: From manager v0.1 pack (manifest NBA-GENERAL-2024). Verify version and dates from the PDF. | AF12: =IF($H12="","",IF($T12="To find","Not started",IF(($C12="")+($D12="")+($E12="")+($G12="")+($I12="")+($M12="")+($O12="")+($S12="")>0,"Missing basic details",IF(AND($T12="Downloaded",($R12="")+($U12="")+($V12="")+(($W12="")*(RIGHT(LOWER($U12),4)=".pdf"))>0),"Add file details",IF(AND($T12="Downloaded",LEN($X12)<>64),"Check SHA-256",IF(AND($Q12="",$R12=""),"Add a URL",IF($S12="No","Not official - replace",IF($M12="Not verified","Verify status","OK")))))))) | AG12: Needs fix | AH12: Auto-QA 12-Oct-2026 | AI12: 1) Downloaded but missing: Version / Edition, Issued On. | 2) Set Current Status from the document (Current / Superseded ...).
A13: S-009 | B13: Intern A | C13: 1. Accreditation & Quality | D13: NBA | E13: accreditation | F13: Authoritative quality framework | G13: NBA-003 | H13: NBA UG Engineering Tier II Manual | I13: Manual | M13: Not verified | O13: Affiliated engineering programmes | Q13: https://www.nbaind.org/Downloads/Documents | R13: https://www.nbaind.org/files/Publication/PublicationTitles/NBA_UGEngg_Tier_II_Manual_Format_20250121123952.pdf | S13: Yes | T13: Downloaded | U13: https://drive.google.com/file/d/1nAVg_Y7d-ohG76D-MZme6rA1rgDleGzg/view?usp=drive_link | V13: 4659 | W13: 230 | X13: 792a4a2c75ad936cd9d1d9e8f2023907de280576a09f8add47ab67e46d49a7f4 | Y13: No | Z13: 3 | AA13: document_index | AD13: From manager v0.1 pack (manifest NBA-UG-TIER-II-2025). Verify version and dates from the PDF. | AF13: =IF($H13="","",IF($T13="To find","Not started",IF(($C13="")+($D13="")+($E13="")+($G13="")+($I13="")+($M13="")+($O13="")+($S13="")>0,"Missing basic details",IF(AND($T13="Downloaded",($R13="")+($U13="")+($V13="")+(($W13="")*(RIGHT(LOWER($U13),4)=".pdf"))>0),"Add file details",IF(AND($T13="Downloaded",LEN($X13)<>64),"Check SHA-256",IF(AND($Q13="",$R13=""),"Add a URL",IF($S13="No","Not official - replace",IF($M13="Not verified","Verify status","OK")))))))) | AG13: Needs fix | AH13: Auto-QA 12-Oct-2026 | AI13: 1) Downloaded but missing: Version / Edition, Issued On. | 2) Set Current Status from the document (Current / Superseded ...).
A14: S-010 | B14: Intern A | C14: 1. Accreditation & Quality | D14: NBA | E14: accreditation | F14: Authoritative quality framework | G14: NBA-004 | H14: NBA UG Engineering Tier I SAR / Manual | I14: SSR / QIF / SAR | M14: Not verified | T14: Downloaded | U14: https://drive.google.com/drive/folders/1pPXX8mvcFTuRihRpCImDKyImx-A1k4Ey?usp=drive_link | Y14: No | Z14: 3 | AA14: document_index | AE14: https://www.nbaind.org/Downloads/Documents | AF14: =IF($H14="","",IF($T14="To find","Not started",IF(($C14="")+($D14="")+($E14="")+($G14="")+($I14="")+($M14="")+($O14="")+($S14="")>0,"Missing basic details",IF(AND($T14="Downloaded",($R14="")+($U14="")+($V14="")+(($W14="")*(RIGHT(LOWER($U14),4)=".pdf"))>0),"Add file details",IF(AND($T14="Downloaded",LEN($X14)<>64),"Check SHA-256",IF(AND($Q14="",$R14=""),"Add a URL",IF($S14="No","Not official - replace",IF($M14="Not verified","Verify status","OK")))))))) | AG14: Needs fix | AH14: Auto-QA 12-Oct-2026 | AI14: 1) Drive link is a FOLDER - link the exact file (drive.google.com/file/d/...). | 2) Downloaded but missing: Direct Document URL, File Size (KB), SHA-256 Checksum, Version / Edition, Issued On. | 3) Set Current Status from the document (Current / Superseded ...). | 4) Fill "Applies To".
A15: S-011 | B15: Intern A | C15: 1. Accreditation & Quality | D15: NBA | E15: accreditation | F15: Authoritative quality framework | G15: NBA-005 | H15: NBA Diploma Engineering SAR / Manual | I15: SSR / QIF / SAR | M15: Not verified | O15: Polytechnics | T15: Downloaded | U15: https://drive.google.com/drive/folders/1pPXX8mvcFTuRihRpCImDKyImx-A1k4Ey?usp=drive_link | Y15: No | Z15: 3 | AA15: document_index | AE15: https://www.nbaind.org/Downloads/Documents | AF15: =IF($H15="","",IF($T15="To find","Not started",IF(($C15="")+($D15="")+($E15="")+($G15="")+($I15="")+($M15="")+($O15="")+($S15="")>0,"Missing basic details",IF(AND($T15="Downloaded",($R15="")+($U15="")+($V15="")+(($W15="")*(RIGHT(LOWER($U15),4)=".pdf"))>0),"Add file details",IF(AND($T15="Downloaded",LEN($X15)<>64),"Check SHA-256",IF(AND($Q15="",$R15=""),"Add a URL",IF($S15="No","Not official - replace",IF($M15="Not verified","Verify status","OK")))))))) | AG15: Needs fix | AH15: Auto-QA 12-Oct-2026 | AI15: 1) Drive link is a FOLDER - link the exact file (drive.google.com/file/d/...). | 2) Downloaded but missing: Direct Document URL, File Size (KB), SHA-256 Checksum, Version / Edition, Issued On. | 3) Set Current Status from the document (Current / Superseded ...).
A16: S-012 | B16: Intern A | C16: 1. Accreditation & Quality | D16: NBA | E16: accreditation | F16: Authoritative quality framework | G16: NBA-006 | H16: NBA PG Engineering SAR / Manual | I16: SSR / QIF / SAR | M16: Not verified | T16: Downloaded | U16: https://drive.google.com/drive/folders/1pPXX8mvcFTuRihRpCImDKyImx-A1k4Ey?usp=drive_link | Y16: No | Z16: 3 | AA16: document_index | AE16: https://www.nbaind.org/Downloads/Documents | AF16: =IF($H16="","",IF($T16="To find","Not started",IF(($C16="")+($D16="")+($E16="")+($G16="")+($I16="")+($M16="")+($O16="")+($S16="")>0,"Missing basic details",IF(AND($T16="Downloaded",($R16="")+($U16="")+($V16="")+(($W16="")*(RIGHT(LOWER($U16),4)=".pdf"))>0),"Add file details",IF(AND($T16="Downloaded",LEN($X16)<>64),"Check SHA-256",IF(AND($Q16="",$R16=""),"Add a URL",IF($S16="No","Not official - replace",IF($M16="Not verified","Verify status","OK")))))))) | AG16: Needs fix | AH16: Auto-QA 12-Oct-2026 | AI16: 1) Drive link is a FOLDER - link the exact file (drive.google.com/file/d/...). | 2) Downloaded but missing: Direct Document URL, File Size (KB), SHA-256 Checksum, Version / Edition, Issued On. | 3) Set Current Status from the document (Current / Superseded ...). | 4) Fill "Applies To".
A17: S-013 | B17: Intern A | C17: 1. Accreditation & Quality | D17: NBA | E17: accreditation | F17: Authoritative quality framework | G17: NBA-007 | H17: NBA Management (MBA / PGDM) SAR / Manual | I17: SSR / QIF / SAR | M17: Not verified | T17: Downloaded | U17: https://drive.google.com/drive/folders/1pPXX8mvcFTuRihRpCImDKyImx-A1k4Ey?usp=drive_link | Y17: No | Z17: 3 | AA17: document_index | AE17: https://www.nbaind.org/Downloads/Documents | AF17: =IF($H17="","",IF($T17="To find","Not started",IF(($C17="")+($D17="")+($E17="")+($G17="")+($I17="")+($M17="")+($O17="")+($S17="")>0,"Missing basic details",IF(AND($T17="Downloaded",($R17="")+($U17="")+($V17="")+(($W17="")*(RIGHT(LOWER($U17),4)=".pdf"))>0),"Add file details",IF(AND($T17="Downloaded",LEN($X17)<>64),"Check SHA-256",IF(AND($Q17="",$R17=""),"Add a URL",IF($S17="No","Not official - replace",IF($M17="Not verified","Verify status","OK")))))))) | AG17: Needs fix | AH17: Auto-QA 12-Oct-2026 | AI17: 1) Drive link is a FOLDER - link the exact file (drive.google.com/file/d/...). | 2) Downloaded but missing: Direct Document URL, File Size (KB), SHA-256 Checksum, Version / Edition, Issued On. | 3) Set Current Status from the document (Current / Superseded ...). | 4) Fill "Applies To".
A18: S-014 | B18: Intern A | C18: 1. Accreditation & Quality | D18: NBA | E18: accreditation | F18: Authoritative quality framework | G18: NBA-008 | H18: NBA Pre-Qualifiers (one row per programme type) | I18: Manual | M18: Not verified | T18: Downloaded | U18: https://drive.google.com/drive/folders/1pPXX8mvcFTuRihRpCImDKyImx-A1k4Ey?usp=drive_link | Y18: No | Z18: 3 | AA18: document_index | AD18: Add one row per programme type you find. | AE18: https://www.nbaind.org/Downloads/Documents | AF18: =IF($H18="","",IF($T18="To find","Not started",IF(($C18="")+($D18="")+($E18="")+($G18="")+($I18="")+($M18="")+($O18="")+($S18="")>0,"Missing basic details",IF(AND($T18="Downloaded",($R18="")+($U18="")+($V18="")+(($W18="")*(RIGHT(LOWER($U18),4)=".pdf"))>0),"Add file details",IF(AND($T18="Downloaded",LEN($X18)<>64),"Check SHA-256",IF(AND($Q18="",$R18=""),"Add a URL",IF($S18="No","Not official - replace",IF($M18="Not verified","Verify status","OK")))))))) | AG18: Needs fix | AH18: Auto-QA 12-Oct-2026 | AI18: 1) Title is still the template placeholder - replace with the exact official title, one row per document (add rows for the others). | 2) Drive link is a FOLDER - link the exact file (drive.google.com/file/d/...). | 3) Downloaded but missing: Direct Document URL, File Size (KB), SHA-256 Checksum, Version / Edition, Issued On. | 4) Set Current Status from the document (Current / Superseded ...). | 5) Fill "Applies To".
A19: S-015 | B19: Intern A | C19: 1. Accreditation & Quality | D19: NBA | E19: accreditation | F19: Authoritative quality framework | G19: NBA-009 | H19: NBA Evaluation Guidelines and visit-document list | I19: Guideline | M19: Not verified | T19: Downloaded | U19: https://drive.google.com/drive/folders/1pPXX8mvcFTuRihRpCImDKyImx-A1k4Ey?usp=drive_link | Y19: No | Z19: 3 | AA19: document_index | AE19: https://www.nbaind.org/Downloads/Documents | AF19: =IF($H19="","",IF($T19="To find","Not started",IF(($C19="")+($D19="")+($E19="")+($G19="")+($I19="")+($M19="")+($O19="")+($S19="")>0,"Missing basic details",IF(AND($T19="Downloaded",($R19="")+($U19="")+($V19="")+(($W19="")*(RIGHT(LOWER($U19),4)=".pdf"))>0),"Add file details",IF(AND($T19="Downloaded",LEN($X19)<>64),"Check SHA-256",IF(AND($Q19="",$R19=""),"Add a URL",IF($S19="No","Not official - replace",IF($M19="Not verified","Verify status","OK")))))))) | AG19: Needs fix | AH19: Auto-QA 12-Oct-2026 | AI19: 1) Drive link is a FOLDER - link the exact file (drive.google.com/file/d/...). | 2) Downloaded but missing: Direct Document URL, File Size (KB), SHA-256 Checksum, Version / Edition, Issued On. | 3) Set Current Status from the document (Current / Superseded ...). | 4) Fill "Applies To".
A20: S-016 | B20: Intern A | C20: 1. Accreditation & Quality | D20: NIRF | E20: ranking | F20: Authoritative quality framework | G20: NIRF-001 | H20: NIRF Documents portal (register snapshot) | I20: Register page | M20: Not verified | O20: Eligible HEIs | Q20: https://www.nirfindia.org/Home/Documents | R20: https://www.nirfindia.org/Home/Documents | S20: Yes | T20: Downloaded | U20: https://drive.google.com/drive/folders/1YeYVR0csD4GIeFYpq0YxGOtX83Hnj4ya?usp=drive_link | V20: 24 | X20: 221c7924fb4a2787ebc06b83d9306c53bf5de3a6720da93825b02b2578d17293 | Y20: No | Z20: 12 | AA20: document_index | AD20: Snapshot from manager v0.1 pack. Use this page to find NIRF-002 and NIRF-003. | AF20: =IF($H20="","",IF($T20="To find","Not started",IF(($C20="")+($D20="")+($E20="")+($G20="")+($I20="")+($M20="")+($O20="")+($S20="")>0,"Missing basic details",IF(AND($T20="Downloaded",($R20="")+($U20="")+($V20="")+(($W20="")*(RIGHT(LOWER($U20),4)=".pdf"))>0),"Add file details",IF(AND($T20="Downloaded",LEN($X20)<>64),"Check SHA-256",IF(AND($Q20="",$R20=""),"Add a URL",IF($S20="No","Not official - replace",IF($M20="Not verified","Verify status","OK")))))))) | AG20: Needs fix | AH20: Auto-QA 12-Oct-2026 | AI20: 1) Drive link is a FOLDER - link the exact file (drive.google.com/file/d/...). | 2) Downloaded but missing: Version / Edition, Issued On. | 3) Set Current Status from the document (Current / Superseded ...).
A21: S-017 | B21: Intern A | C21: 1. Accreditation & Quality | D21: NIRF | E21: ranking | F21: Authoritative quality framework | G21: NIRF-002 | H21: NIRF ranking methodology - overall and category-wise | I21: Methodology | M21: Not verified | O21: Eligible HEIs | T21: Downloaded | U21: https://drive.google.com/drive/folders/1YeYVR0csD4GIeFYpq0YxGOtX83Hnj4ya?usp=drive_link | Y21: No | Z21: 12 | AA21: document_index | AD21: Add one row per category methodology. | AE21: https://www.nirfindia.org/Home/Documents | AF21: =IF($H21="","",IF($T21="To find","Not started",IF(($C21="")+($D21="")+($E21="")+($G21="")+($I21="")+($M21="")+($O21="")+($S21="")>0,"Missing basic details",IF(AND($T21="Downloaded",($R21="")+($U21="")+($V21="")+(($W21="")*(RIGHT(LOWER($U21),4)=".pdf"))>0),"Add file details",IF(AND($T21="Downloaded",LEN($X21)<>64),"Check SHA-256",IF(AND($Q21="",$R21=""),"Add a URL",IF($S21="No","Not official - replace",IF($M21="Not verified","Verify status","OK")))))))) | AG21: Needs fix | AH21: Auto-QA 12-Oct-2026 | AI21: 1) Drive link is a FOLDER - link the exact file (drive.google.com/file/d/...). | 2) Downloaded but missing: Direct Document URL, File Size (KB), SHA-256 Checksum, Version / Edition, Issued On. | 3) Set Current Status from the document (Current / Superseded ...).
A22: S-018 | B22: Intern A | C22: 1. Accreditation & Quality | D22: NIRF | E22: ranking | F22: Authoritative quality framework | G22: NIRF-003 | H22: NIRF Data Capturing System (DCS) manual and parameter definitions | I22: Manual | M22: Not verified | O22: Eligible HEIs | T22: Downloaded | U22: https://drive.google.com/drive/folders/1YeYVR0csD4GIeFYpq0YxGOtX83Hnj4ya?usp=drive_link | Y22: No | Z22: 12 | AA22: document_index | AE22: https://www.nirfindia.org/Home/Documents | AF22: =IF($H22="","",IF($T22="To find","Not started",IF(($C22="")+($D22="")+($E22="")+($G22="")+($I22="")+($M22="")+($O22="")+($S22="")>0,"Missing basic details",IF(AND($T22="Downloaded",($R22="")+($U22="")+($V22="")+(($W22="")*(RIGHT(LOWER($U22),4)=".pdf"))>0),"Add file details",IF(AND($T22="Downloaded",LEN($X22)<>64),"Check SHA-256",IF(AND($Q22="",$R22=""),"Add a URL",IF($S22="No","Not official - replace",IF($M22="Not verified","Verify status","OK")))))))) | AG22: Needs fix | AH22: Auto-QA 12-Oct-2026 | AI22: 1) Drive link is a FOLDER - link the exact file (drive.google.com/file/d/...). | 2) Downloaded but missing: Direct Document URL, File Size (KB), SHA-256 Checksum, Version / Edition, Issued On. | 3) Set Current Status from the document (Current / Superseded ...).
A23: S-019 | B23: Intern A | C23: 2. Higher-Education Regulation | D23: UGC | E23: regulatory | F23: Mandatory | G23: UGC-001 | H23: UGC Regulations register (register snapshot) | I23: Register page | M23: Not verified | O23: HEIs | Q23: https://www.ugc.gov.in/Regulations | R23: https://www.ugc.gov.in/Regulations | S23: Yes | T23: Downloaded | U23: https://drive.google.com/drive/folders/1ZHdieeVU_fvMWe8NT_z3RLyr0nvQ5419?usp=drive_link | V23: 137 | X23: e87101365423d386be1724200cc838210e19dd8adad0c6566f779e2433160895 | Y23: No | Z23: 1 | AA23: document_index | AD23: Snapshot from manager v0.1 pack. Main starting point for UGC-003 to UGC-022. | AF23: =IF($H23="","",IF($T23="To find","Not started",IF(($C23="")+($D23="")+($E23="")+($G23="")+($I23="")+($M23="")+($O23="")+($S23="")>0,"Missing basic details",IF(AND($T23="Downloaded",($R23="")+($U23="")+($V23="")+(($W23="")*(RIGHT(LOWER($U23),4)=".pdf"))>0),"Add file details",IF(AND($T23="Downloaded",LEN($X23)<>64),"Check SHA-256",IF(AND($Q23="",$R23=""),"Add a URL",IF($S23="No","Not official - replace",IF($M23="Not verified","Verify status","OK")))))))) | AG23: Needs fix | AH23: Auto-QA 12-Oct-2026 | AI23: 1) Drive link is a FOLDER - link the exact file (drive.google.com/file/d/...). | 2) Downloaded but missing: Version / Edition, Issued On. | 3) Set Current Status from the document (Current / Superseded ...).
A24: S-020 | B24: Intern A | C24: 2. Higher-Education Regulation | D24: UGC | E24: regulatory | F24: Good-practice standard | G24: UGC-002 | H24: UGC Guidelines register (register snapshot) | I24: Register page | M24: Not verified | O24: HEIs | Q24: https://www.ugc.gov.in/Guideline | R24: https://www.ugc.gov.in/Guideline | S24: Yes | T24: Downloaded | U24: https://drive.google.com/drive/folders/1ZHdieeVU_fvMWe8NT_z3RLyr0nvQ5419?usp=drive_link | V24: 98 | X24: 1039c92b2a08b7333d78db48dc003ddfbe64df2a05d1c99c75f7407d6e97c808 | Y24: No | Z24: 1 | AA24: document_index | AD24: Snapshot from manager v0.1 pack. | AF24: =IF($H24="","",IF($T24="To find","Not started",IF(($C24="")+($D24="")+($E24="")+($G24="")+($I24="")+($M24="")+($O24="")+($S24="")>0,"Missing basic details",IF(AND($T24="Downloaded",($R24="")+($U24="")+($V24="")+(($W24="")*(RIGHT(LOWER($U24),4)=".pdf"))>0),"Add file details",IF(AND($T24="Downloaded",LEN($X24)<>64),"Check SHA-256",IF(AND($Q24="",$R24=""),"Add a URL",IF($S24="No","Not official - replace",IF($M24="Not verified","Verify status","OK")))))))) | AG24: Needs fix | AH24: Auto-QA 12-Oct-2026 | AI24: 1) Drive link is a FOLDER - link the exact file (drive.google.com/file/d/...). | 2) Downloaded but missing: Version / Edition, Issued On. | 3) Set Current Status from the document (Current / Superseded ...).
A25: S-021 | B25: Intern A | C25: 2. Higher-Education Regulation | D25: UGC | E25: regulatory | F25: Mandatory | G25: UGC-003 | H25: UGC Minimum Standards of Instruction for the Grant of UG and PG Degrees Regulations, 2025 | I25: Regulation | M25: Not verified | O25: Universities and colleges | T25: Downloaded | U25: https://drive.google.com/drive/folders/1ZHdieeVU_fvMWe8NT_z3RLyr0nvQ5419?usp=drive_link | Y25: No | Z25: 3 | AA25: document_index | AE25: https://www.ugc.gov.in/Regulations | AF25: =IF($H25="","",IF($T25="To find","Not started",IF(($C25="")+($D25="")+($E25="")+($G25="")+($I25="")+($M25="")+($O25="")+($S25="")>0,"Missing basic details",IF(AND($T25="Downloaded",($R25="")+($U25="")+($V25="")+(($W25="")*(RIGHT(LOWER($U25),4)=".pdf"))>0),"Add file details",IF(AND($T25="Downloaded",LEN($X25)<>64),"Check SHA-256",IF(AND($Q25="",$R25=""),"Add a URL",IF($S25="No","Not official - replace",IF($M25="Not verified","Verify status","OK")))))))) | AG25: Needs fix | AH25: Auto-QA 12-Oct-2026 | AI25: 1) Drive link is a FOLDER - link the exact file (drive.google.com/file/d/...). | 2) Downloaded but missing: Direct Document URL, File Size (KB), SHA-256 Checksum, Version / Edition, Issued On. | 3) Set Current Status from the document (Current / Superseded ...).
A26: S-022 | B26: Intern A | C26: 2. Higher-Education Regulation | D26: UGC | E26: regulatory | F26: Mandatory | G26: UGC-004 | H26: UGC Minimum Qualifications (teachers and academic staff) Regulations and amendments | I26: Regulation | M26: Not verified | O26: Universities and colleges | T26: Downloaded | U26: https://drive.google.com/drive/folders/1ZHdieeVU_fvMWe8NT_z3RLyr0nvQ5419?usp=drive_link | Y26: No | Z26: 3 | AA26: document_index | AD26: Add a separate row for each amendment. | AE26: https://www.ugc.gov.in/Regulations | AF26: =IF($H26="","",IF($T26="To find","Not started",IF(($C26="")+($D26="")+($E26="")+($G26="")+($I26="")+($M26="")+($O26="")+($S26="")>0,"Missing basic details",IF(AND($T26="Downloaded",($R26="")+($U26="")+($V26="")+(($W26="")*(RIGHT(LOWER($U26),4)=".pdf"))>0),"Add file details",IF(AND($T26="Downloaded",LEN($X26)<>64),"Check SHA-256",IF(AND($Q26="",$R26=""),"Add a URL",IF($S26="No","Not official - replace",IF($M26="Not verified","Verify status","OK")))))))) | AG26: Needs fix | AH26: Auto-QA 12-Oct-2026 | AI26: 1) Drive link is a FOLDER - link the exact file (drive.google.com/file/d/...). | 2) Downloaded but missing: Direct Document URL, File Size (KB), SHA-256 Checksum, Version / Edition, Issued On. | 3) Set Current Status from the document (Current / Superseded ...).
A27: S-023 | B27: Intern A | C27: 2. Higher-Education Regulation | D27: UGC | E27: regulatory | F27: Mandatory | G27: UGC-005 | H27: UGC Promotion of Academic Integrity and Prevention of Plagiarism Regulations, 2018 | I27: Regulation | M27: Not verified | O27: HEIs | T27: Downloaded | U27: https://drive.google.com/drive/folders/1ZHdieeVU_fvMWe8NT_z3RLyr0nvQ5419?usp=drive_link | Y27: No | Z27: 3 | AA27: document_index | AE27: https://www.ugc.gov.in/Regulations | AF27: =IF($H27="","",IF($T27="To find","Not started",IF(($C27="")+($D27="")+($E27="")+($G27="")+($I27="")+($M27="")+($O27="")+($S27="")>0,"Missing basic details",IF(AND($T27="Downloaded",($R27="")+($U27="")+($V27="")+(($W27="")*(RIGHT(LOWER($U27),4)=".pdf"))>0),"Add file details",IF(AND($T27="Downloaded",LEN($X27)<>64),"Check SHA-256",IF(AND($Q27="",$R27=""),"Add a URL",IF($S27="No","Not official - replace",IF($M27="Not verified","Verify status","OK")))))))) | AG27: Needs fix | AH27: Auto-QA 12-Oct-2026 | AI27: 1) Drive link is a FOLDER - link the exact file (drive.google.com/file/d/...). | 2) Downloaded but missing: Direct Document URL, File Size (KB), SHA-256 Checksum, Version / Edition, Issued On. | 3) Set Current Status from the document (Current / Superseded ...).
A28: S-024 | B28: Intern A | C28: 2. Higher-Education Regulation | D28: UGC | E28: regulatory | F28: Good-practice standard | G28: UGC-006 | H28: UGC guidelines for Institutional Development Plans (IDP) | I28: Guideline | M28: Not verified | O28: HEIs | T28: Downloaded | U28: https://drive.google.com/drive/folders/1ZHdieeVU_fvMWe8NT_z3RLyr0nvQ5419?usp=drive_link | Y28: No | Z28: 12 | AA28: document_index | AE28: https://www.ugc.gov.in/Guideline | AF28: =IF($H28="","",IF($T28="To find","Not started",IF(($C28="")+($D28="")+($E28="")+($G28="")+($I28="")+($M28="")+($O28="")+($S28="")>0,"Missing basic details",IF(AND($T28="Downloaded",($R28="")+($U28="")+($V28="")+(($W28="")*(RIGHT(LOWER($U28),4)=".pdf"))>0),"Add file details",IF(AND($T28="Downloaded",LEN($X28)<>64),"Check SHA-256",IF(AND($Q28="",$R28=""),"Add a URL",IF($S28="No","Not official - replace",IF($M28="Not verified","Verify status","OK")))))))) | AG28: Needs fix | AH28: Auto-QA 12-Oct-2026 | AI28: 1) Drive link is a FOLDER - link the exact file (drive.google.com/file/d/...). | 2) Downloaded but missing: Direct Document URL, File Size (KB), SHA-256 Checksum, Version / Edition, Issued On. | 3) Set Current Status from the document (Current / Superseded ...).
A29: S-025 | B29: Intern A | C29: 7. Research, Innovation & Impact | D29: UGC | E29: regulatory | F29: Good-practice standard | G29: UGC-007 | H29: UGC guidelines for Research and Development Cells in HEIs | I29: Guideline | M29: Not verified | O29: HEIs | T29: Downloaded | U29: https://drive.google.com/file/d/1-W89tsVwlg87IXnmo9kLluhV4j9HgV1o/view?usp=drive_link | Y29: No | Z29: 12 | AA29: document_index | AE29: https://www.ugc.gov.in/Guideline | AF29: =IF($H29="","",IF($T29="To find","Not started",IF(($C29="")+($D29="")+($E29="")+($G29="")+($I29="")+($M29="")+($O29="")+($S29="")>0,"Missing basic details",IF(AND($T29="Downloaded",($R29="")+($U29="")+($V29="")+(($W29="")*(RIGHT(LOWER($U29),4)=".pdf"))>0),"Add file details",IF(AND($T29="Downloaded",LEN($X29)<>64),"Check SHA-256",IF(AND($Q29="",$R29=""),"Add a URL",IF($S29="No","Not official - replace",IF($M29="Not verified","Verify status","OK")))))))) | AG29: Needs fix | AH29: Auto-QA 12-Oct-2026 | AI29: 1) Downloaded but missing: Direct Document URL, File Size (KB), SHA-256 Checksum, Version / Edition, Issued On, Pages. | 2) Set Current Status from the document (Current / Superseded ...).
A30: S-026 | B30: Intern A | C30: 4. Student Protection & Inclusion | D30: UGC | E30: regulatory | F30: Good-practice standard | G30: UGC-008 | H30: UGC Accessibility Guidelines and Standards for HEIs | I30: Guideline | M30: Not verified | O30: HEIs | T30: Downloaded | U30: https://drive.google.com/file/d/1w24SO93KZWXoLHJePCz2k2FMgyvEW81h/view?usp=drive_link | Y30: No | Z30: 12 | AA30: document_index | AE30: https://www.ugc.gov.in/Guideline | AF30: =IF($H30="","",IF($T30="To find","Not started",IF(($C30="")+($D30="")+($E30="")+($G30="")+($I30="")+($M30="")+($O30="")+($S30="")>0,"Missing basic details",IF(AND($T30="Downloaded",($R30="")+($U30="")+($V30="")+(($W30="")*(RIGHT(LOWER($U30),4)=".pdf"))>0),"Add file details",IF(AND($T30="Downloaded",LEN($X30)<>64),"Check SHA-256",IF(AND($Q30="",$R30=""),"Add a URL",IF($S30="No","Not official - replace",IF($M30="Not verified","Verify status","OK")))))))) | AG30: Needs fix | AH30: Auto-QA 12-Oct-2026 | AI30: 1) Downloaded but missing: Direct Document URL, File Size (KB), SHA-256 Checksum, Version / Edition, Issued On, Pages. | 2) Set Current Status from the document (Current / Superseded ...).
A31: S-027 | B31: Intern A | C31: 4. Student Protection & Inclusion | D31: UGC | E31: regulatory | F31: Good-practice standard | G31: UGC-009 | H31: UGC guidelines on equitable opportunities for socio-economically disadvantaged groups (SEDG) | I31: Guideline | M31: Not verified | O31: HEIs | T31: Downloaded | U31: https://drive.google.com/file/d/1zzWY39CGx8soqpcCMi32KadwmjTI8TJI/view?usp=drive_link | Y31: No | Z31: 12 | AA31: document_index | AE31: https://www.ugc.gov.in/Guideline | AF31: =IF($H31="","",IF($T31="To find","Not started",IF(($C31="")+($D31="")+($E31="")+($G31="")+($I31="")+($M31="")+($O31="")+($S31="")>0,"Missing basic details",IF(AND($T31="Downloaded",($R31="")+($U31="")+($V31="")+(($W31="")*(RIGHT(LOWER($U31),4)=".pdf"))>0),"Add file details",IF(AND($T31="Downloaded",LEN($X31)<>64),"Check SHA-256",IF(AND($Q31="",$R31=""),"Add a URL",IF($S31="No","Not official - replace",IF($M31="Not verified","Verify status","OK")))))))) | AG31: Needs fix | AH31: Auto-QA 12-Oct-2026 | AI31: 1) Downloaded but missing: Direct Document URL, File Size (KB), SHA-256 Checksum, Version / Edition, Issued On, Pages. | 2) Set Current Status from the document (Current / Superseded ...).
A32: S-028 | B32: Intern A | C32: 2. Higher-Education Regulation | D32: UGC | E32: regulatory | F32: Mandatory | G32: UGC-010 | H32: UGC Open and Distance Learning and Online Programmes Regulations | I32: Regulation | M32: Not verified | O32: Eligible HEIs | T32: Downloaded | U32: https://drive.google.com/drive/folders/1ZHdieeVU_fvMWe8NT_z3RLyr0nvQ5419?usp=drive_link | Y32: No | Z32: 3 | AA32: document_index | AE32: https://www.ugc.gov.in/Regulations | AF32: =IF($H32="","",IF($T32="To find","Not started",IF(($C32="")+($D32="")+($E32="")+($G32="")+($I32="")+($M32="")+($O32="")+($S32="")>0,"Missing basic details",IF(AND($T32="Downloaded",($R32="")+($U32="")+($V32="")+(($W32="")*(RIGHT(LOWER($U32),4)=".pdf"))>0),"Add file details",IF(AND($T32="Downloaded",LEN($X32)<>64),"Check SHA-256",IF(AND($Q32="",$R32=""),"Add a URL",IF($S32="No","Not official - replace",IF($M32="Not verified","Verify status","OK")))))))) | AG32: Needs fix | AH32: Auto-QA 12-Oct-2026 | AI32: 1) Drive link is a FOLDER - link the exact file (drive.google.com/file/d/...). | 2) Downloaded but missing: Direct Document URL, File Size (KB), SHA-256 Checksum, Version / Edition, Issued On. | 3) Set Current Status from the document (Current / Superseded ...).
A33: S-029 | B33: Intern A | C33: 2. Higher-Education Regulation | D33: UGC | E33: regulatory | F33: Mandatory | G33: UGC-011 | H33: UGC PhD regulations (minimum standards and procedures for award of PhD) | I33: Regulation | M33: Not verified | T33: Downloaded | U33: https://drive.google.com/drive/folders/1ZHdieeVU_fvMWe8NT_z3RLyr0nvQ5419?usp=drive_link | Y33: No | Z33: 3 | AA33: document_index | AE33: https://www.ugc.gov.in/Regulations | AF33: =IF($H33="","",IF($T33="To find","Not started",IF(($C33="")+($D33="")+($E33="")+($G33="")+($I33="")+($M33="")+($O33="")+($S33="")>0,"Missing basic details",IF(AND($T33="Downloaded",($R33="")+($U33="")+($V33="")+(($W33="")*(RIGHT(LOWER($U33),4)=".pdf"))>0),"Add file details",IF(AND($T33="Downloaded",LEN($X33)<>64),"Check SHA-256",IF(AND($Q33="",$R33=""),"Add a URL",IF($S33="No","Not official - replace",IF($M33="Not verified","Verify status","OK")))))))) | AG33: Needs fix | AH33: Auto-QA 12-Oct-2026 | AI33: 1) Drive link is a FOLDER - link the exact file (drive.google.com/file/d/...). | 2) Downloaded but missing: Direct Document URL, File Size (KB), SHA-256 Checksum, Version / Edition, Issued On. | 3) Set Current Status from the document (Current / Superseded ...). | 4) Fill "Applies To".
A34: S-030 | B34: Intern A | C34: 2. Higher-Education Regulation | D34: UGC | E34: regulatory | F34: Mandatory | G34: UGC-012 | H34: UGC regulations for conferment of autonomous status on colleges | I34: Regulation | M34: Not verified | O34: Autonomous colleges | T34: Downloaded | U34: https://drive.google.com/drive/folders/1ZHdieeVU_fvMWe8NT_z3RLyr0nvQ5419?usp=drive_link | Y34: No | Z34: 3 | AA34: document_index | AE34: https://www.ugc.gov.in/Regulations | AF34: =IF($H34="","",IF($T34="To find","Not started",IF(($C34="")+($D34="")+($E34="")+($G34="")+($I34="")+($M34="")+($O34="")+($S34="")>0,"Missing basic details",IF(AND($T34="Downloaded",($R34="")+($U34="")+($V34="")+(($W34="")*(RIGHT(LOWER($U34),4)=".pdf"))>0),"Add file details",IF(AND($T34="Downloaded",LEN($X34)<>64),"Check SHA-256",IF(AND($Q34="",$R34=""),"Add a URL",IF($S34="No","Not official - replace",IF($M34="Not verified","Verify status","OK")))))))) | AG34: Needs fix | AH34: Auto-QA 12-Oct-2026 | AI34: 1) Drive link is a FOLDER - link the exact file (drive.google.com/file/d/...). | 2) Downloaded but missing: Direct Document URL, File Size (KB), SHA-256 Checksum, Version / Edition, Issued On. | 3) Set Current Status from the document (Current / Superseded ...).
A35: S-031 | B35: Intern A | C35: 2. Higher-Education Regulation | D35: UGC | E35: regulatory | F35: Mandatory | G35: UGC-013 | H35: UGC institutional recognition requirements | I35: Regulation | M35: Not verified | T35: Downloaded | U35: https://drive.google.com/drive/folders/1ZHdieeVU_fvMWe8NT_z3RLyr0nvQ5419?usp=drive_link | Y35: No | Z35: 3 | AA35: document_index | AD35: Identify which current regulations cover recognition; one row each. | AE35: https://www.ugc.gov.in/Regulations | AF35: =IF($H35="","",IF($T35="To find","Not started",IF(($C35="")+($D35="")+($E35="")+($G35="")+($I35="")+($M35="")+($O35="")+($S35="")>0,"Missing basic details",IF(AND($T35="Downloaded",($R35="")+($U35="")+($V35="")+(($W35="")*(RIGHT(LOWER($U35),4)=".pdf"))>0),"Add file details",IF(AND($T35="Downloaded",LEN($X35)<>64),"Check SHA-256",IF(AND($Q35="",$R35=""),"Add a URL",IF($S35="No","Not official - replace",IF($M35="Not verified","Verify status","OK")))))))) | AG35: Needs fix | AH35: Auto-QA 12-Oct-2026 | AI35: 1) Drive link is a FOLDER - link the exact file (drive.google.com/file/d/...). | 2) Downloaded but missing: Direct Document URL, File Size (KB), SHA-256 Checksum, Version / Edition, Issued On. | 3) Set Current Status from the document (Current / Superseded ...). | 4) Fill "Applies To".
A36: S-032 | B36: Intern A | C36: 2. Higher-Education Regulation | D36: UGC | E36: regulatory | F36: Good-practice standard | G36: UGC-014 | H36: UGC internship guidelines | I36: Guideline | M36: Not verified | T36: Downloaded | U36: https://drive.google.com/drive/folders/1ZHdieeVU_fvMWe8NT_z3RLyr0nvQ5419?usp=drive_link | Y36: No | Z36: 12 | AA36: document_index | AE36: https://www.ugc.gov.in/Guideline | AF36: =IF($H36="","",IF($T36="To find","Not started",IF(($C36="")+($D36="")+($E36="")+($G36="")+($I36="")+($M36="")+($O36="")+($S36="")>0,"Missing basic details",IF(AND($T36="Downloaded",($R36="")+($U36="")+($V36="")+(($W36="")*(RIGHT(LOWER($U36),4)=".pdf"))>0),"Add file details",IF(AND($T36="Downloaded",LEN($X36)<>64),"Check SHA-256",IF(AND($Q36="",$R36=""),"Add a URL",IF($S36="No","Not official - replace",IF($M36="Not verified","Verify status","OK")))))))) | AG36: Needs fix | AH36: Auto-QA 12-Oct-2026 | AI36: 1) Drive link is a FOLDER - link the exact file (drive.google.com/file/d/...). | 2) Downloaded but missing: Direct Document URL, File Size (KB), SHA-256 Checksum, Version / Edition, Issued On. | 3) Set Current Status from the document (Current / Superseded ...). | 4) Fill "Applies To".
A37: S-033 | B37: Intern A | C37: 2. Higher-Education Regulation | D37: UGC | E37: regulatory | F37: Good-practice standard | G37: UGC-015 | H37: UGC guidelines on academia-industry linkage | I37: Guideline | M37: Not verified | T37: Downloaded | U37: https://drive.google.com/drive/folders/1ZHdieeVU_fvMWe8NT_z3RLyr0nvQ5419?usp=drive_link | Y37: No | Z37: 12 | AA37: document_index | AE37: https://www.ugc.gov.in/Guideline | AF37: =IF($H37="","",IF($T37="To find","Not started",IF(($C37="")+($D37="")+($E37="")+($G37="")+($I37="")+($M37="")+($O37="")+($S37="")>0,"Missing basic details",IF(AND($T37="Downloaded",($R37="")+($U37="")+($V37="")+(($W37="")*(RIGHT(LOWER($U37),4)=".pdf"))>0),"Add file details",IF(AND($T37="Downloaded",LEN($X37)<>64),"Check SHA-256",IF(AND($Q37="",$R37=""),"Add a URL",IF($S37="No","Not official - replace",IF($M37="Not verified","Verify status","OK")))))))) | AG37: Needs fix | AH37: Auto-QA 12-Oct-2026 | AI37: 1) Drive link is a FOLDER - link the exact file (drive.google.com/file/d/...). | 2) Downloaded but missing: Direct Document URL, File Size (KB), SHA-256 Checksum, Version / Edition, Issued On. | 3) Set Current Status from the document (Current / Superseded ...). | 4) Fill "Applies To".
A38: S-034 | B38: Intern A | C38: 2. Higher-Education Regulation | D38: UGC | E38: regulatory | F38: Good-practice standard | G38: UGC-016 | H38: UGC guidelines on internationalisation of higher education | I38: Guideline | M38: Not verified | T38: Downloaded | U38: https://drive.google.com/drive/folders/1ZHdieeVU_fvMWe8NT_z3RLyr0nvQ5419?usp=drive_link | Y38: No | Z38: 12 | AA38: document_index | AE38: https://www.ugc.gov.in/Guideline | AF38: =IF($H38="","",IF($T38="To find","Not started",IF(($C38="")+($D38="")+($E38="")+($G38="")+($I38="")+($M38="")+($O38="")+($S38="")>0,"Missing basic details",IF(AND($T38="Downloaded",($R38="")+($U38="")+($V38="")+(($W38="")*(RIGHT(LOWER($U38),4)=".pdf"))>0),"Add file details",IF(AND($T38="Downloaded",LEN($X38)<>64),"Check SHA-256",IF(AND($Q38="",$R38=""),"Add a URL",IF($S38="No","Not official - replace",IF($M38="Not verified","Verify status","OK")))))))) | AG38: Needs fix | AH38: Auto-QA 12-Oct-2026 | AI38: 1) Drive link is a FOLDER - link the exact file (drive.google.com/file/d/...). | 2) Downloaded but missing: Direct Document URL, File Size (KB), SHA-256 Checksum, Version / Edition, Issued On. | 3) Set Current Status from the document (Current / Superseded ...). | 4) Fill "Applies To".
A39: S-035 | B39: Intern A | C39: 2. Higher-Education Regulation | D39: UGC | E39: regulatory | F39: Good-practice standard | G39: UGC-017 | H39: UGC guidelines on multiple entry and exit | I39: Guideline | M39: Not verified | T39: Downloaded | U39: https://drive.google.com/drive/folders/1ZHdieeVU_fvMWe8NT_z3RLyr0nvQ5419?usp=drive_link | Y39: No | Z39: 12 | AA39: document_index | AE39: https://www.ugc.gov.in/Guideline | AF39: =IF($H39="","",IF($T39="To find","Not started",IF(($C39="")+($D39="")+($E39="")+($G39="")+($I39="")+($M39="")+($O39="")+($S39="")>0,"Missing basic details",IF(AND($T39="Downloaded",($R39="")+($U39="")+($V39="")+(($W39="")*(RIGHT(LOWER($U39),4)=".pdf"))>0),"Add file details",IF(AND($T39="Downloaded",LEN($X39)<>64),"Check SHA-256",IF(AND($Q39="",$R39=""),"Add a URL",IF($S39="No","Not official - replace",IF($M39="Not verified","Verify status","OK")))))))) | AG39: Needs fix | AH39: Auto-QA 12-Oct-2026 | AI39: 1) Drive link is a FOLDER - link the exact file (drive.google.com/file/d/...). | 2) Downloaded but missing: Direct Document URL, File Size (KB), SHA-256 Checksum, Version / Edition, Issued On. | 3) Set Current Status from the document (Current / Superseded ...). | 4) Fill "Applies To".
A40: S-036 | B40: Intern A | C40: 2. Higher-Education Regulation | D40: UGC | E40: regulatory | F40: Good-practice standard | G40: UGC-018 | H40: UGC guidelines on public self-disclosure by HEIs | I40: Guideline | M40: Not verified | T40: Downloaded | U40: https://drive.google.com/drive/folders/1ZHdieeVU_fvMWe8NT_z3RLyr0nvQ5419?usp=drive_link | Y40: No | Z40: 12 | AA40: document_index | AE40: https://www.ugc.gov.in/Guideline | AF40: =IF($H40="","",IF($T40="To find","Not started",IF(($C40="")+($D40="")+($E40="")+($G40="")+($I40="")+($M40="")+($O40="")+($S40="")>0,"Missing basic details",IF(AND($T40="Downloaded",($R40="")+($U40="")+($V40="")+(($W40="")*(RIGHT(LOWER($U40),4)=".pdf"))>0),"Add file details",IF(AND($T40="Downloaded",LEN($X40)<>64),"Check SHA-256",IF(AND($Q40="",$R40=""),"Add a URL",IF($S40="No","Not official - replace",IF($M40="Not verified","Verify status","OK")))))))) | AG40: Needs fix | AH40: Auto-QA 12-Oct-2026 | AI40: 1) Drive link is a FOLDER - link the exact file (drive.google.com/file/d/...). | 2) Downloaded but missing: Direct Document URL, File Size (KB), SHA-256 Checksum, Version / Edition, Issued On. | 3) Set Current Status from the document (Current / Superseded ...). | 4) Fill "Applies To".
A41: S-037 | B41: Intern A | C41: 2. Higher-Education Regulation | D41: UGC | E41: regulatory | F41: Good-practice standard | G41: UGC-019 | H41: UGC guidelines on multidisciplinary education | I41: Guideline | M41: Not verified | T41: Downloaded | U41: https://drive.google.com/drive/folders/1ZHdieeVU_fvMWe8NT_z3RLyr0nvQ5419?usp=drive_link | Y41: No | Z41: 12 | AA41: document_index | AE41: https://www.ugc.gov.in/Guideline | AF41: =IF($H41="","",IF($T41="To find","Not started",IF(($C41="")+($D41="")+($E41="")+($G41="")+($I41="")+($M41="")+($O41="")+($S41="")>0,"Missing basic details",IF(AND($T41="Downloaded",($R41="")+($U41="")+($V41="")+(($W41="")*(RIGHT(LOWER($U41),4)=".pdf"))>0),"Add file details",IF(AND($T41="Downloaded",LEN($X41)<>64),"Check SHA-256",IF(AND($Q41="",$R41=""),"Add a URL",IF($S41="No","Not official - replace",IF($M41="Not verified","Verify status","OK")))))))) | AG41: Needs fix | AH41: Auto-QA 12-Oct-2026 | AI41: 1) Drive link is a FOLDER - link the exact file (drive.google.com/file/d/...). | 2) Downloaded but missing: Direct Document URL, File Size (KB), SHA-256 Checksum, Version / Edition, Issued On. | 3) Set Current Status from the document (Current / Superseded ...). | 4) Fill "Applies To".
...

Sheet Progress
A1: Progress - updates automatically from the Source Register
A3: By intern
A4: Intern | B4: Rows Assigned | C4: To Find | D4: Downloaded | E4: Link Only / Licensed | F4: Blocked / Not Available | G4: Row Check OK | H4: QA Verified | I4: % Collected | J4: % QA Verified
A5: =Lists!A3 | B5: =COUNTIFS('Source Register'!$B$5:$B$400,$A5,'Source Register'!$H$5:$H$400,"<>") | C5: =COUNTIFS('Source Register'!$B$5:$B$400,$A5,'Source Register'!$T$5:$T$400,"To find") | D5: =COUNTIFS('Source Register'!$B$5:$B$400,$A5,'Source Register'!$T$5:$T$400,"Downloaded") | E5: =COUNTIFS('Source Register'!$B$5:$B$400,$A5,'Source Register'!$T$5:$T$400,"Found - link only")+COUNTIFS('Source Register'!$B$5:$B$400,$A5,'Source Register'!$T$5:$T$400,"Licensed - link only") | F5: =COUNTIFS('Source Register'!$B$5:$B$400,$A5,'Source Register'!$T$5:$T$400,"Blocked - portal/login")+COUNTIFS('Source Register'!$B$5:$B$400,$A5,'Source Register'!$T$5:$T$400,"Not available") | G5: =COUNTIFS('Source Register'!$B$5:$B$400,$A5,'Source Register'!$AF$5:$AF$400,"OK") | H5: =COUNTIFS('Source Register'!$B$5:$B$400,$A5,'Source Register'!$AG$5:$AG$400,"Verified") | I5: =IF(B5=0,0,(B5-C5)/B5) | J5: =IF(B5=0,0,H5/B5)
A6: =Lists!A4 | B6: =COUNTIFS('Source Register'!$B$5:$B$400,$A6,'Source Register'!$H$5:$H$400,"<>") | C6: =COUNTIFS('Source Register'!$B$5:$B$400,$A6,'Source Register'!$T$5:$T$400,"To find") | D6: =COUNTIFS('Source Register'!$B$5:$B$400,$A6,'Source Register'!$T$5:$T$400,"Downloaded") | E6: =COUNTIFS('Source Register'!$B$5:$B$400,$A6,'Source Register'!$T$5:$T$400,"Found - link only")+COUNTIFS('Source Register'!$B$5:$B$400,$A6,'Source Register'!$T$5:$T$400,"Licensed - link only") | F6: =COUNTIFS('Source Register'!$B$5:$B$400,$A6,'Source Register'!$T$5:$T$400,"Blocked - portal/login")+COUNTIFS('Source Register'!$B$5:$B$400,$A6,'Source Register'!$T$5:$T$400,"Not available") | G6: =COUNTIFS('Source Register'!$B$5:$B$400,$A6,'Source Register'!$AF$5:$AF$400,"OK") | H6: =COUNTIFS('Source Register'!$B$5:$B$400,$A6,'Source Register'!$AG$5:$AG$400,"Verified") | I6: =IF(B6=0,0,(B6-C6)/B6) | J6: =IF(B6=0,0,H6/B6)
A7: Total | B7: =SUM(B5:B6) | C7: =SUM(C5:C6) | D7: =SUM(D5:D6) | E7: =SUM(E5:E6) | F7: =SUM(F5:F6) | G7: =SUM(G5:G6) | H7: =SUM(H5:H6) | I7: =IF(B7=0,0,(B7-C7)/B7) | J7: =IF(B7=0,0,H7/B7)
A10: By category
A11: Category | B11: Rows | C11: To Find | D11: Downloaded | E11: Link Only / Licensed | F11: Blocked / Not Available | G11: Row Check OK | H11: QA Verified | I11: % Collected
A12: =Lists!B3 | B12: =COUNTIFS('Source Register'!$C$5:$C$400,$A12,'Source Register'!$H$5:$H$400,"<>") | C12: =COUNTIFS('Source Register'!$C$5:$C$400,$A12,'Source Register'!$T$5:$T$400,"To find") | D12: =COUNTIFS('Source Register'!$C$5:$C$400,$A12,'Source Register'!$T$5:$T$400,"Downloaded") | E12: =COUNTIFS('Source Register'!$C$5:$C$400,$A12,'Source Register'!$T$5:$T$400,"Found - link only")+COUNTIFS('Source Register'!$C$5:$C$400,$A12,'Source Register'!$T$5:$T$400,"Licensed - link only") | F12: =COUNTIFS('Source Register'!$C$5:$C$400,$A12,'Source Register'!$T$5:$T$400,"Blocked - portal/login")+COUNTIFS('Source Register'!$C$5:$C$400,$A12,'Source Register'!$T$5:$T$400,"Not available") | G12: =COUNTIFS('Source Register'!$C$5:$C$400,$A12,'Source Register'!$AF$5:$AF$400,"OK") | H12: =COUNTIFS('Source Register'!$C$5:$C$400,$A12,'Source Register'!$AG$5:$AG$400,"Verified") | I12: =IF(B12=0,0,(B12-C12)/B12)
A13: =Lists!B4 | B13: =COUNTIFS('Source Register'!$C$5:$C$400,$A13,'Source Register'!$H$5:$H$400,"<>") | C13: =COUNTIFS('Source Register'!$C$5:$C$400,$A13,'Source Register'!$T$5:$T$400,"To find") | D13: =COUNTIFS('Source Register'!$C$5:$C$400,$A13,'Source Register'!$T$5:$T$400,"Downloaded") | E13: =COUNTIFS('Source Register'!$C$5:$C$400,$A13,'Source Register'!$T$5:$T$400,"Found - link only")+COUNTIFS('Source Register'!$C$5:$C$400,$A13,'Source Register'!$T$5:$T$400,"Licensed - link only") | F13: =COUNTIFS('Source Register'!$C$5:$C$400,$A13,'Source Register'!$T$5:$T$400,"Blocked - portal/login")+COUNTIFS('Source Register'!$C$5:$C$400,$A13,'Source Register'!$T$5:$T$400,"Not available") | G13: =COUNTIFS('Source Register'!$C$5:$C$400,$A13,'Source Register'!$AF$5:$AF$400,"OK") | H13: =COUNTIFS('Source Register'!$C$5:$C$400,$A13,'Source Register'!$AG$5:$AG$400,"Verified") | I13: =IF(B13=0,0,(B13-C13)/B13)
A14: =Lists!B5 | B14: =COUNTIFS('Source Register'!$C$5:$C$400,$A14,'Source Register'!$H$5:$H$400,"<>") | C14: =COUNTIFS('Source Register'!$C$5:$C$400,$A14,'Source Register'!$T$5:$T$400,"To find") | D14: =COUNTIFS('Source Register'!$C$5:$C$400,$A14,'Source Register'!$T$5:$T$400,"Downloaded") | E14: =COUNTIFS('Source Register'!$C$5:$C$400,$A14,'Source Register'!$T$5:$T$400,"Found - link only")+COUNTIFS('Source Register'!$C$5:$C$400,$A14,'Source Register'!$T$5:$T$400,"Licensed - link only") | F14: =COUNTIFS('Source Register'!$C$5:$C$400,$A14,'Source Register'!$T$5:$T$400,"Blocked - portal/login")+COUNTIFS('Source Register'!$C$5:$C$400,$A14,'Source Register'!$T$5:$T$400,"Not available") | G14: =COUNTIFS('Source Register'!$C$5:$C$400,$A14,'Source Register'!$AF$5:$AF$400,"OK") | H14: =COUNTIFS('Source Register'!$C$5:$C$400,$A14,'Source Register'!$AG$5:$AG$400,"Verified") | I14: =IF(B14=0,0,(B14-C14)/B14)
A15: =Lists!B6 | B15: =COUNTIFS('Source Register'!$C$5:$C$400,$A15,'Source Register'!$H$5:$H$400,"<>") | C15: =COUNTIFS('Source Register'!$C$5:$C$400,$A15,'Source Register'!$T$5:$T$400,"To find") | D15: =COUNTIFS('Source Register'!$C$5:$C$400,$A15,'Source Register'!$T$5:$T$400,"Downloaded") | E15: =COUNTIFS('Source Register'!$C$5:$C$400,$A15,'Source Register'!$T$5:$T$400,"Found - link only")+COUNTIFS('Source Register'!$C$5:$C$400,$A15,'Source Register'!$T$5:$T$400,"Licensed - link only") | F15: =COUNTIFS('Source Register'!$C$5:$C$400,$A15,'Source Register'!$T$5:$T$400,"Blocked - portal/login")+COUNTIFS('Source Register'!$C$5:$C$400,$A15,'Source Register'!$T$5:$T$400,"Not available") | G15: =COUNTIFS('Source Register'!$C$5:$C$400,$A15,'Source Register'!$AF$5:$AF$400,"OK") | H15: =COUNTIFS('Source Register'!$C$5:$C$400,$A15,'Source Register'!$AG$5:$AG$400,"Verified") | I15: =IF(B15=0,0,(B15-C15)/B15)
